<?xml version="1.0" encoding="utf-8"?>
<!-- This URDF was automatically created by SolidWorks to URDF Exporter! Originally created by Stephen Brawner (brawner@gmail.com) 
     Commit Version: 1.6.0-4-g7f85cfe  Build Version: 1.6.7995.38578
     For more information, please see http://wiki.ros.org/sw_urdf_exporter -->
<robot
  name="P3Bot_description">
  <link name="world">
  </link>
  <link name="rotation_link">
  </link>

  <link
    name="base_link">
    <inertial>
      <origin
        xyz="-0.0002775 0.00074547 0.08326"
        rpy="0 0 0" />
      <mass
        value="60.4447" />
      <inertia
        ixx="0.11198"
        ixy="-0.00021409"
        ixz="-4.7645E-05"
        iyy="0.078806"
        iyz="0.00018784"
        izz="0.16136" />
    </inertial>
    <visual>
      <origin
        xyz="0 0 0"
        rpy="0 0 0" />
      <geometry>
        <mesh
          filename="p3bot_description/meshes/base_link.STL" />
      </geometry>
      <material
        name="">
        <color
          rgba="0.69804 0.69804 0.69804 1" />
      </material>
    </visual>
    <collision>
      <origin
        xyz="0 0 0"
        rpy="0 0 0" />
      <geometry>
        <mesh
          filename="p3bot_description/meshes/base_link.STL" />
      </geometry>
    </collision>
  </link>

  <!-- //////////////////////////////////////////// Joints to move the robot //////////////////////////////////// -->

  <joint name="base_rotation_joint" type="revolute">
    <origin rpy="0 0 0" xyz="0 0 0"/>
    <parent link="world"/>
    <child link="rotation_link"/>
    <axis xyz="0 0 1"/>
    <limit effort="87" lower="-999999" upper="999999" velocity="4.0"/>
  </joint>

  <joint name="base_translation_joint" type="prismatic">
    <origin rpy="0 0 0" xyz="0 0 0"/>
    <parent link="rotation_link"/>
    <child link="base_link"/>
    <axis xyz="1 0 0"/>
    <limit effort="87" lower="-999999" upper="999999" velocity="4.0"/>
  </joint>

  <!-- ////////////////////////////////////////////////////////////////////////////////////////////////////////// -->

  <link
    name="low_body">
    <inertial>
      <origin
        xyz="9.9572E-05 -0.074879 0.19249"
        rpy="0 0 0" />
      <mass
        value="4.3937" />
      <inertia
        ixx="0.1746"
        ixy="-5.366E-05"
        ixz="3.4275E-05"
        iyy="0.14504"
        iyz="0.026965"
        izz="0.1126" />
    </inertial>
    <visual>
      <origin
        xyz="0 0 0"
        rpy="0 0 0" />
      <geometry>
        <mesh
          filename="p3bot_description/meshes/low_body.STL" />
      </geometry>
      <material
        name="">
        <color
          rgba="0.69804 0.69804 0.69804 1" />
      </material>
    </visual>
    <collision>
      <origin
        xyz="0 0 0"
        rpy="0 0 0" />
      <geometry>
        <mesh
          filename="p3bot_description/meshes/low_body.STL" />
      </geometry>
    </collision>
  </link>
  <joint
    name="base_link2low_body"
    type="fixed">
    <origin
      xyz="0 0 0.21"
      rpy="0 0 0" />
    <parent
      link="base_link" />
    <child
      link="low_body" />
    <axis
      xyz="0 0 0" />
  </joint>
  <link
    name="chess">
    <inertial>
      <origin
        xyz="3.8834E-05 0.059571 0.24898"
        rpy="0 0 0" />
      <mass
        value="11.017" />
      <inertia
        ixx="0.14132"
        ixy="-4.16E-06"
        ixz="-2.7151E-05"
        iyy="0.20507"
        iyz="-0.010384"
        izz="0.11596" />
    </inertial>
    <visual>
      <origin
        xyz="0 0 0"
        rpy="0 0 0" />
      <geometry>
        <mesh
          filename="p3bot_description/meshes/chess.STL" />
      </geometry>
      <material
        name="">
        <color
          rgba="0.69804 0.69804 0.69804 1" />
      </material>
    </visual>
    <collision>
      <origin
        xyz="0 0 0"
        rpy="0 0 0" />
      <geometry>
        <mesh
          filename="p3bot_description/meshes/chess.STL" />
      </geometry>
    </collision>
  </link>
  <joint
    name="low_body2chess"
    type="fixed">
    <origin
      xyz="0 -0.13951 0.46"
      rpy="0 0 0" />
    <parent
      link="low_body" />
    <child
      link="chess" />
    <axis
      xyz="0 0 0" />
  </joint>

  <link
    name="rs_helios">
    <inertial>
      <origin xyz="0.0012997 -9.8495E-05 -0.014539" rpy="0 0 0" />
      <mass value="0.81549" />
      <inertia ixx="0.0009369" ixy="-5.0942E-07" ixz="-2.6194E-06" 
               iyy="0.00092707" iyz="5.9141E-07" izz="0.001563" />
    </inertial>
    <visual>
      <origin xyz="0 0 0" rpy="0 0 0" />
      <geometry>
        <mesh
          filename="p3bot_description/meshes/rs_helios.STL" />
      </geometry>
      <material
        name="black">
        <color rgba="0 0 0 1" />
      </material>
    </visual>
    <collision>
      <origin xyz="0 0 0" rpy="0 0 0" />
      <geometry>
        <mesh
          filename="p3bot_description/meshes/rs_helios.STL" />
      </geometry>
    </collision>
  </link>
  <joint
    name="chess2rs_helios"
    type="fixed">
    <origin
      xyz="0 0.0095122 0.53425"
      rpy="0 0 0" />
    <parent
      link="chess" />
    <child
      link="rs_helios" />
    <axis
      xyz="0 0 0" />
  </joint>
  <link
    name="cap">
    <inertial>
      <origin
        xyz="1.2649E-06 1.2124E-06 0.019457"
        rpy="0 0 0" />
      <mass
        value="0.076724" />
      <inertia
        ixx="9.1333E-05"
        ixy="2.7874E-08"
        ixz="2.2465E-09"
        iyy="9.7004E-05"
        iyz="1.7834E-09"
        izz="0.00012452" />
    </inertial>
    <visual>
      <origin
        xyz="0 0 0"
        rpy="0 0 0" />
      <geometry>
        <mesh
          filename="p3bot_description/meshes/cap.STL" />
      </geometry>
      <material
        name="">
        <color
          rgba="0.69804 0.69804 0.69804 1" />
      </material>
    </visual>
    <collision>
      <origin
        xyz="0 0 0"
        rpy="0 0 0" />
      <geometry>
        <mesh
          filename="p3bot_description/meshes/cap.STL" />
      </geometry>
    </collision>
  </link>
  <joint
    name="rs_helios2cap"
    type="fixed">
    <origin
      xyz="-0.00038758 0.001468 0.04575"
      rpy="0 0 0" />
    <parent
      link="rs_helios" />
    <child
      link="cap" />
    <axis
      xyz="0 0 0" />
  </joint>
  <link
    name="ricoh_theta_z1">
    <inertial>
      <origin
        xyz="1.3047E-05 -0.010465 -0.041268"
        rpy="0 0 0" />
      <mass
        value="0.13859" />
      <inertia
        ixx="0.00017166"
        ixy="-1.775E-09"
        ixz="1.2162E-08"
        iyy="0.00019024"
        iyz="8.7184E-10"
        izz="3.0109E-05" />
    </inertial>
    <visual>
      <origin
        xyz="0 0 0"
        rpy="0 0 0" />
      <geometry>
        <mesh
          filename="p3bot_description/meshes/ricoh_theta_z1.STL" />
      </geometry>
      <material
        name="black">
        <color
          rgba="0 0 0 1" />
      </material>
    </visual>
    <collision>
      <origin
        xyz="0 0 0"
        rpy="0 0 0" />
      <geometry>
        <mesh
          filename="p3bot_description/meshes/ricoh_theta_z1.STL" />
      </geometry>
    </collision>
  </link>
  <joint
    name="cap2ricoh_theta_z1"
    type="fixed">
    <origin
      xyz="0 0.010465 0.15634"
      rpy="0 0 0" />
    <parent
      link="cap" />
    <child
      link="ricoh_theta_z1" />
    <axis
      xyz="0 0 0" />
  </joint>

  <!-- /////////////////////////////////////////////// Right arm /////////////////////////////////////////////// -->
  
  <link
    name="right_arm">
    <inertial>
      <origin xyz="-0.00098435 0.00010048 0.078051" rpy="0 0 0" />
        <mass value="1.697"/>
        <inertia ixx="0.004622" ixy="9E-06" ixz="6E-05" iyy="0.004495" iyz="9E-06" izz="0.002079"/>
    </inertial>
    <visual>
      <origin xyz="0 0 0" rpy="0 0 0" />
      <geometry>
        <mesh
          filename="p3bot_description/meshes/arm_base_link.STL" />
      </geometry>
        <material name="gray">
        <color rgba="0.75294 0.75294 0.75294 1"/>
      </material>
    </visual>
    <collision>
      <origin xyz="0 0 0" rpy="0 0 0" />
      <geometry>
        <mesh
          filename="p3bot_description/meshes/arm_base_link.STL" />
      </geometry>
    </collision>
  </link>
  <joint
    name="chess2right_arm"
    type="fixed">
    <origin xyz="0.05305 0.066416 0.34039" rpy="2.0071 0 1.5708" />
    <parent link="chess" />
    <child link="right_arm" />
    <axis xyz="0 0 0" />
  </joint>

  <link name="right_arm_shoulder_link">
    <inertial>
      <origin rpy="0 0 0" xyz="-2.3E-05 -0.010364 -0.07336"/>
      <mass value="1.3773"/>
      <inertia ixx="0.00457" ixy="1E-06" ixz="2E-06" iyy="0.004831" iyz="0.000448" izz="0.001409"/>
    </inertial>
    <visual>
      <origin rpy="0 0 0" xyz="0 0 0"/>
      <geometry>
        <mesh filename="p3bot_description/meshes/shoulder_link.STL"/>
      </geometry>
      <material name="gray">
        <color rgba="0.75294 0.75294 0.75294 1"/>
      </material>
    </visual>
    <collision>
      <origin rpy="0 0 0" xyz="0 0 0"/>
      <geometry>
        <mesh filename="p3bot_description/meshes/shoulder_link.STL"/>
      </geometry>
    </collision>
  </link>
  <joint name="right_arm_joint_1" type="continuous">
    <origin rpy="3.1416 2.7629E-18 -4.9305E-36" xyz="0 0 0.15643"/>
    <parent link="right_arm"/>
    <child link="right_arm_shoulder_link"/>
    <axis xyz="0 0 1"/>
    <limit effort="39" velocity="1.3963"/>
  </joint>
  <link name="right_arm_half_arm_1_link">
    <inertial>
      <origin rpy="0 0 0" xyz="-4.4E-05 -0.09958 -0.013278"/>
      <mass value="1.1636"/>
      <inertia ixx="0.011088" ixy="5E-06" ixz="0" iyy="0.001072" iyz="-0.000691" izz="0.011255"/>
    </inertial>
    <visual>
      <origin rpy="0 0 0" xyz="0 0 0"/>
      <geometry>
        <mesh filename="p3bot_description/meshes/half_arm_1_link.STL"/>
      </geometry>
      <material name="gray">
        <color rgba="0.75294 0.75294 0.75294 1"/>
      </material>
    </visual>
    <collision>
      <origin rpy="0 0 0" xyz="0 0 0"/>
      <geometry>
        <mesh filename="p3bot_description/meshes/half_arm_1_link.STL"/>
      </geometry>
    </collision>
  </link>
  <joint name="right_arm_joint_2" type="revolute">
    <origin rpy="1.5708 2.1343E-17 -1.1102E-16" xyz="0 0.005375 -0.12838"/>
    <parent link="right_arm_shoulder_link"/>
    <child link="right_arm_half_arm_1_link"/>
    <axis xyz="0 0 1"/>
    <limit effort="39" lower="-2.24" upper="2.24" velocity="1.3963"/>
  </joint>
  <link name="right_arm_half_arm_2_link">
    <inertial>
      <origin rpy="0 0 0" xyz="-4.4E-05 -0.006641 -0.117892"/>
      <mass value="1.1636"/>
      <inertia ixx="0.010932" ixy="0" ixz="-7E-06" iyy="0.011127" iyz="0.000606" izz="0.001043"/>
    </inertial>
    <visual>
      <origin rpy="0 0 0" xyz="0 0 0"/>
      <geometry>
        <mesh filename="p3bot_description/meshes/half_arm_2_link.STL"/>
      </geometry>
      <material name="gray">
        <color rgba="0.75294 0.75294 0.75294 1"/>
      </material>
    </visual>
    <collision>
      <origin rpy="0 0 0" xyz="0 0 0"/>
      <geometry>
        <mesh filename="p3bot_description/meshes/half_arm_2_link.STL"/>
      </geometry>
    </collision>
  </link>
  <joint name="right_arm_joint_3" type="continuous">
    <origin rpy="-1.5708 1.2326E-32 -2.9122E-16" xyz="0 -0.21038 -0.006375"/>
    <parent link="right_arm_half_arm_1_link"/>
    <child link="right_arm_half_arm_2_link"/>
    <axis xyz="0 0 1"/>
    <limit effort="39" velocity="1.3963"/>
  </joint>
  <link name="right_arm_forearm_link">
    <inertial>
      <origin rpy="0 0 0" xyz="-1.8E-05 -0.075478 -0.015006"/>
      <mass value="0.9302"/>
      <inertia ixx="0.008147" ixy="-1E-06" ixz="0" iyy="0.000631" iyz="-0.0005" izz="0.008316"/>
    </inertial>
    <visual>
      <origin rpy="0 0 0" xyz="0 0 0"/>
      <geometry>
        <mesh filename="p3bot_description/meshes/forearm_link.STL"/>
      </geometry>
      <material name="gray">
        <color rgba="0.75294 0.75294 0.75294 1"/>
      </material>
    </visual>
    <collision>
      <origin rpy="0 0 0" xyz="0 0 0"/>
      <geometry>
        <mesh filename="p3bot_description/meshes/forearm_link.STL"/>
      </geometry>
    </collision>
  </link>
  <joint name="right_arm_joint_4" type="revolute">
    <origin rpy="1.5708 -6.6954E-17 -1.6653E-16" xyz="0 0.006375 -0.21038"/>
    <parent link="right_arm_half_arm_2_link"/>
    <child link="right_arm_forearm_link"/>
    <axis xyz="0 0 1"/>
    <limit effort="39" lower="-2.57" upper="2.57" velocity="1.3963"/>
  </joint>
  <link name="right_arm_spherical_wrist_1_link">
    <inertial>
      <origin rpy="0 0 0" xyz="1E-06 -0.009432 -0.063883"/>
      <mass value="0.6781"/>
      <inertia ixx="0.001596" ixy="0" ixz="0" iyy="0.001607" iyz="0.000256" izz="0.000399"/>
    </inertial>
    <visual>
      <origin rpy="0 0 0" xyz="0 0 0"/>
      <geometry>
        <mesh filename="p3bot_description/meshes/spherical_wrist_1_link.STL"/>
      </geometry>
      <material name="gray">
        <color rgba="0.75294 0.75294 0.75294 1"/>
      </material>
    </visual>
    <collision>
      <origin rpy="0 0 0" xyz="0 0 0"/>
      <geometry>
        <mesh filename="p3bot_description/meshes/spherical_wrist_1_link.STL"/>
      </geometry>
    </collision>
  </link>
  <joint name="right_arm_joint_5" type="continuous">
    <origin rpy="-1.5708 2.2204E-16 -6.373E-17" xyz="0 -0.20843 -0.006375"/>
    <parent link="right_arm_forearm_link"/>
    <child link="right_arm_spherical_wrist_1_link"/>
    <axis xyz="0 0 1"/>
    <limit effort="9" velocity="1.2218"/>
  </joint>
  <link name="right_arm_spherical_wrist_2_link">
    <inertial>
      <origin rpy="0 0 0" xyz="1E-06 -0.045483 -0.00965"/>
      <mass value="0.6781"/>
      <inertia ixx="0.001641" ixy="0" ixz="0" iyy="0.00041" iyz="-0.000278" izz="0.001641"/>
    </inertial>
    <visual>
      <origin rpy="0 0 0" xyz="0 0 0"/>
      <geometry>
        <mesh filename="p3bot_description/meshes/spherical_wrist_2_link.STL"/>
      </geometry>
      <material name="gray">
        <color rgba="0.75294 0.75294 0.75294 1"/>
      </material>
    </visual>
    <collision>
      <origin rpy="0 0 0" xyz="0 0 0"/>
      <geometry>
        <mesh filename="p3bot_description/meshes/spherical_wrist_2_link.STL"/>
      </geometry>
    </collision>
  </link>
  <joint name="right_arm_joint_6" type="revolute">
    <origin rpy="1.5708 9.2076E-28 -8.2157E-15" xyz="0 0.00017505 -0.10593"/>
    <parent link="right_arm_spherical_wrist_1_link"/>
    <child link="right_arm_spherical_wrist_2_link"/>
    <axis xyz="0 0 1"/>
    <limit effort="9" lower="-2.09" upper="2.09" velocity="1.2218"/>
  </joint>
  <link name="right_arm_bracelet_link">
    <inertial>
      <origin rpy="0 0 0" xyz="0.000281 0.011402 -0.029798"/>
      <mass value="0.5"/>
      <inertia ixx="0.000587" ixy="3E-06" ixz="3E-06" iyy="0.000369" iyz="-0.000118" izz="0.000609"/>
    </inertial>
    <visual>
      <origin rpy="0 0 0" xyz="0 0 0"/>
      <geometry>
        <mesh filename="p3bot_description/meshes/bracelet_with_vision_link.STL"/>
      </geometry>
      <material name="gray">
        <color rgba="0.75294 0.75294 0.75294 1"/>
      </material>
    </visual>
    <collision>
      <origin rpy="0 0 0" xyz="0 0 0"/>
      <geometry>
        <mesh filename="p3bot_description/meshes/bracelet_with_vision_link.STL"/>
      </geometry>
    </collision>
  </link>
  <joint name="right_arm_joint_7" type="continuous">
    <origin rpy="-1.5708 -5.5511E-17 9.6396E-17" xyz="0 -0.10593 -0.00017505"/>
    <parent link="right_arm_spherical_wrist_2_link"/>
    <child link="right_arm_bracelet_link"/>
    <axis xyz="0 0 1"/>
    <limit effort="9" velocity="1.2218"/>
  </joint>
  <link name="right_arm_end_effector_link"/>
  <joint name="right_arm_end_effector" type="fixed">
    <origin rpy="3.14159265358979 1.09937075168372E-32 0" xyz="0 0 -0.0615250000000001"/>
    <parent link="right_arm_bracelet_link"/>
    <child link="right_arm_end_effector_link"/>
    <axis xyz="0 0 0"/>
  </joint>
  <link name="right_arm_camera_link"/>
  <joint name="right_arm_camera_module" type="fixed">
    <origin rpy="3.14159265358979 3.14159265358979 0" xyz="0 0.05639 -0.00305"/>
    <parent link="right_arm_end_effector_link"/>
    <child link="right_arm_camera_link"/>
  </joint>
  <link name="right_arm_camera_depth_frame"/>
  <joint name="right_arm_depth_module" type="fixed">
    <origin rpy="3.14159265358979 3.14159265358979 0" xyz="0.0275 0.066 -0.00305"/>
    <parent link="right_arm_end_effector_link"/>
    <child link="right_arm_camera_depth_frame"/>
  </joint>
  <link name="right_arm_camera_color_frame"/>
  <joint name="right_arm_color_module" type="fixed">
    <origin rpy="3.14159265358979 3.14159265358979 0" xyz="0 0.05639 -0.00305"/>
    <parent link="right_arm_end_effector_link"/>
    <child link="right_arm_camera_color_frame"/>
  </joint>
  <!-- This line was removed by Kinova because we replaced the transmission file with our own 
    <xacro:include filename="$(find robotiq_2f_85_gripper_visualization)/urdf/robotiq_arg2f_transmission.xacro" /> -->
  <!-- Tool frame used by the arm -->
  <link name="right_arm_tool_frame"/>
  <joint name="right_arm_tool_frame_joint" type="fixed">
    <origin rpy="0 0 0" xyz="0 0 0.120"/>
    <parent link="right_arm_end_effector_link"/>
    <child link="right_arm_tool_frame"/>
    <axis xyz="0 0 0"/>
  </joint>

</robot>